Workbook

Sheet Sheet1
A1: 日期_月 | B1: 核代账户id | C1: 核代账户名称 | D1: 广告包名 | E1: 地域 | F1: DSP收入 | G1: 包名区域匹配 | H1: 数鲸归属 | I1: 争议归属 | J1: 备注
A2: 202512 | B2: 368 | C2: Avow GmbH | D2: com.finaccel.android | E2: SA | F2: 54785.83 | G2: =VLOOKUP(D2,'【For 计提】包名对应区域'!A:B,2,0) -> SEA
A3: 202512 | B3: 368 | C3: Avow GmbH | D3: com.wetter.androidclient | E3: WEU/CEE | F3: 36759.96 | G3: =VLOOKUP(D3,'【For 计提】包名对应区域'!A:B,2,0) -> WEU/CEE
A4: 202512 | B4: 368 | C4: Avow GmbH | D4: net.peakgames.Yuzbir | F4: 26876.64 | G4: =VLOOKUP(D4,'【For 计提】包名对应区域'!A:B,2,0) -> NA
A5: 202512 | B5: 8342 | C5: Flymobi Technology Group Limited | D5: com.voicemaker.android | E5: APAC | F5: 26809.7 | G5: =VLOOKUP(D5,'【For 计提】包名对应区域'!A:B,2,0) -> APAC
A6: 202512 | B6: 8342 | C6: Flymobi Technology Group Limited | D6: com.live.soulchill | E6: SEA | F6: 19707.52 | G6: =VLOOKUP(D6,'【For 计提】包名对应区域'!A:B,2,0) -> APAC
A7: 202512 | B7: 368 | C7: Avow GmbH | D7: com.revolut.revolut | F7: 18718.77 | G7: =VLOOKUP(D7,'【For 计提】包名对应区域'!A:B,2,0) -> WEU/CEE
A8: 202512 | B8: 8342 | C8: Flymobi Technology Group Limited | D8: com.hotplay.bricksballs | E8: APAC | F8: 14162.48 | G8: =VLOOKUP(D8,'【For 计提】包名对应区域'!A:B,2,0) -> APAC
A9: 202512 | B9: 368 | C9: Avow GmbH | D9: com.mercadopago.wallet | F9: 13064 | G9: =VLOOKUP(D9,'【For 计提】包名对应区域'!A:B,2,0) -> LATAM
A10: 202512 | B10: 8342 | C10: Flymobi Technology Group Limited | D10: com.xparty.androidapp | E10: APAC | F10: 13012.18 | G10: =VLOOKUP(D10,'【For 计提】包名对应区域'!A:B,2,0) -> APAC
A11: 202512 | B11: 8342 | C11: Flymobi Technology Group Limited | D11: com.voicechat.live.group | E11: APAC | F11: 12969.65 | G11: =VLOOKUP(D11,'【For 计提】包名对应区域'!A:B,2,0) -> APAC
A12: 202512 | B12: 368 | C12: Avow GmbH | F12: 12305.9 | G12: WEU
A13: 202512 | B13: 8342 | C13: Flymobi Technology Group Limited | D13: com.hotplay.babyexcavator | E13: APAC | F13: 11167.48 | G13: =VLOOKUP(D13,'【For 计提】包名对应区域'!A:B,2,0) -> APAC
A14: 202512 | B14: 368 | C14: Avow GmbH | D14: com.tripledot.solitaire | E14: WEU/CEE | F14: 10350.23 | G14: =VLOOKUP(D14,'【For 计提】包名对应区域'!A:B,2,0) -> WEU/CEE
A15: 202512 | B15: 8342 | C15: Flymobi Technology Group Limited | D15: com.wallpaperx.main | F15: 9657.22 | G15: =VLOOKUP(D15,'【For 计提】包名对应区域'!A:B,2,0) -> APAC
A16: 202512 | B16: 8342 | C16: Flymobi Technology Group Limited | D16: com.hotplay.petexplosion | E16: APAC | F16: 9043.54 | G16: =VLOOKUP(D16,'【For 计提】包名对应区域'!A:B,2,0) -> APAC
A17: 202512 | B17: 368 | C17: Avow GmbH | D17: com.axlebolt.standoff2 | E17: MENA | F17: 9032.5 | G17: =VLOOKUP(D17,'【For 计提】包名对应区域'!A:B,2,0) -> CIS
A18: 202512 | B18: 368 | C18: Avow GmbH | D18: com.akbank.android.apps.akbank_direkt | E18: MENA | F18: 8404.81 | G18: =VLOOKUP(D18,'【For 计提】包名对应区域'!A:B,2,0) -> MENA
A19: 202512 | B19: 8342 | C19: Flymobi Technology Group Limited | D19: com.fusionmind.crazydrive | E19: APAC | F19: 7922.91 | G19: =VLOOKUP(D19,'【For 计提】包名对应区域'!A:B,2,0) -> APAC
A20: 202512 | B20: 8342 | C20: Flymobi Technology Group Limited | D20: com.xenalite.androidapp | E20: APAC | F20: 7831.51 | G20: =VLOOKUP(D20,'【For 计提】包名对应区域'!A:B,2,0) -> APAC
A21: 202512 | B21: 8342 | C21: Flymobi Technology Group Limited | D21: com.aultkm.calandexlock | E21: APAC | F21: 7811.68 | G21: =VLOOKUP(D21,'【For 计提】包名对应区域'!A:B,2,0) -> APAC
A22: 202512 | B22: 8342 | C22: Flymobi Technology Group Limited | D22: com.biotalem.deskclock | E22: APAC | F22: 7773.26 | G22: =VLOOKUP(D22,'【For 计提】包名对应区域'!A:B,2,0) -> APAC
A23: 202512 | B23: 8342 | C23: Flymobi Technology Group Limited | D23: com.fruitdrop.combine | E23: WEU/CEE | F23: 7658.54 | G23: =VLOOKUP(D23,'【For 计提】包名对应区域'!A:B,2,0) -> WEU/CEE
A24: 202512 | B24: 8342 | C24: Flymobi Technology Group Limited | D24: com.zombiedefense.battle | E24: WEU/CEE | F24: 7614.91 | G24: =VLOOKUP(D24,'【For 计提】包名对应区域'!A:B,2,0) -> APAC
A25: 202512 | B25: 368 | C25: Avow GmbH | D25: com.zm.watersort | E25: WEU/CEE | F25: 7323.79 | G25: =VLOOKUP(D25,'【For 计提】包名对应区域'!A:B,2,0) -> WEU/CEE
A26: 202512 | B26: 8342 | C26: Flymobi Technology Group Limited | D26: com.gridlock.vault | E26: WEU/CEE | F26: 7187.14 | G26: =VLOOKUP(D26,'【For 计提】包名对应区域'!A:B,2,0) -> APAC
A27: 202512 | B27: 8342 | C27: Flymobi Technology Group Limited | D27: com.fintopia.mxcredmex | E27: LATAM | F27: 6766.43 | G27: =VLOOKUP(D27,'【For 计提】包名对应区域'!A:B,2,0) -> LATAM
... A30: 202512 | B30: 368 | C30: Avow GmbH | D30: com.transferwise.android | E30: WEU/CEE | F30: 6172.01 | G30: =VLOOKUP(D30,'【For 计提】包名对应区域'!A:B,2,0) -> WEU/CEE
A31: 202512 | B31: 368 | C31: Avow GmbH | D31: com.luizalabs.mlapp | F31: 5598.02 | G31: =VLOOKUP(D31,'【For 计提】包名对应区域'!A:B,2,0) -> LATAM
A32: 202512 | B32: 368 | C32: Avow GmbH | D32: com.mobirix.swipebrick2 | F32: 5492.04 | G32: =VLOOKUP(D32,'【For 计提】包名对应区域'!A:B,2,0) -> APAC
A33: 202512 | B33: 368 | C33: Avow GmbH | D33: com.callapp.contacts | E33: SEA | F33: 5440.12 | G33: =VLOOKUP(D33,'【For 计提】包名对应区域'!A:B,2,0) -> MENA
A34: 202512 | B34: 368 | C34: Avow GmbH | D34: com.ticno.olymptrade | E34: SEA | F34: 5363.71 | G34: =VLOOKUP(D34,'【For 计提】包名对应区域'!A:B,2,0) -> SEA
A35: 202512 | B35: 8342 | C35: Flymobi Technology Group Limited | D35: com.hotplay.puzzlegames | E35: APAC | F35: 5260.84 | G35: =VLOOKUP(D35,'【For 计提】包名对应区域'!A:B,2,0) -> APAC
A36: 202512 | B36: 368 | C36: Avow GmbH | D36: com.wolt.android | F36: 5219.62 | G36: =VLOOKUP(D36,'【For 计提】包名对应区域'!A:B,2,0) -> WEU/CEE
A37: 202512 | B37: 368 | C37: Avow GmbH | D37: com.huuuge.casino.slots | F37: 5022.28 | G37: =VLOOKUP(D37,'【For 计提】包名对应区域'!A:B,2,0) -> WEU/CEE
A38: 202512 | B38: 8342 | C38: Flymobi Technology Group Limited | D38: com.fpg.thiefstickman | E38: APAC | F38: 4983.4 | G38: =VLOOKUP(D38,'【For 计提】包名对应区域'!A:B,2,0) -> APAC
A39: 202512 | B39: 8342 | C39: Flymobi Technology Group Limited | D39: com.fpg.snakeclash | E39: APAC | F39: 4914.78 | G39: =VLOOKUP(D39,'【For 计提】包名对应区域'!A:B,2,0) -> APAC
A40: 202512 | B40: 368 | C40: Avow GmbH | D40: com.muba.anuncios | F40: 4846.27 | G40: =VLOOKUP(D40,'【For 计提】包名对应区域'!A:B,2,0) -> WEU/CEE
A41: 202512 | B41: 8342 | C41: Flymobi Technology Group Limited | D41: com.immomo.biz.yaahlan | E41: APAC | F41: 4553.84 | G41: =VLOOKUP(D41,'【For 计提】包名对应区域'!A:B,2,0) -> APAC
A42: 202512 | B42: 8342 | C42: Flymobi Technology Group Limited | D42: com.chatchill.app | F42: 4479.25 | G42: =VLOOKUP(D42,'【For 计提】包名对应区域'!A:B,2,0) -> APAC
...

Sheet 【For 计提】包名对应区域
A1: 客户下包名 | B1: 包名所属区域 | C1: 是否重复
A2: zps.game.pusoy.th | B2: SEA | C2: =COUNTIF(A:A,A2) -> 1
A3: zoom.magnifier.clarity.durable.assist | B3: WEU/CEE | C3: =COUNTIF(A:A,A3) -> 1
A4: zentro.warp.zw | B4: APAC | C4: =COUNTIF(A:A,A4) -> 1
A5: zen.task.zt | B5: APAC | C5: =COUNTIF(A:A,A5) -> 1
A6: zebpay.Application | B6: SA | C6: =COUNTIF(A:A,A6) -> 1
A7: zahleb.me | B7: CIS | C7: =COUNTIF(A:A,A7) -> 1
A8: za.co.travelstart.flapp | B8: APAC | C8: =COUNTIF(A:A,A8) -> 1
A9: yyhg.as.mi | B9: APAC | C9: =COUNTIF(A:A,A9) -> 1
A10: yyhg.ar3.mi | B10: APAC | C10: =COUNTIF(A:A,A10) -> 1
A11: youdrive.today | B11: CIS | C11: =COUNTIF(A:A,A11) -> 1
A12: yay.marvelous.orange.corp | B12: CIS | C12: =COUNTIF(A:A,A12) -> 1
A13: y6uzdaz1.web | B13: APAC | C13: =COUNTIF(A:A,A13) -> 1
... A5580: sg.com.cyclecarriage.mycnc | B5580: SEA | C5580: =COUNTIF(A:A,A5580) -> 1
